Workbook

Sheet Modelo
B1: R$ ´000 | C1: 2022 | D1: 2023 | E1: 2024 | F1: 2025 | G1: 2026E | H1: 2027E | I1: 2028E | J1: 2029E
A2: . | B2: Premissas Operacionais
B3: VGV Lançado | F3: ='Buildup da Receita'!Y6 * 1000 -> 6858000 | G3: 7543800 | H3: 7996428 | I3: 8396249 | J3: 8816062
B4: Crescimento VGV (% YoY) | G4: =G3/F3-1 -> 0.1 | H4: =H3/G3-1 -> 0.06 | I4: =I3/H3-1 -> 0.04999995 | J4: =J3/I3-1 -> 0.050000066
B5: Deduções (% Receita Bruta) | AC5: 0.13 | AD5: 0.16 | AE5: 0.19 | AF5: 0.22 | AG5: 0.25
B6: Margem Bruta (% Receita Líquida) | G6: 0.4 | H6: 0.39 | I6: 0.385 | J6: 0.385 | AB6: 0.34 | AC6: -0.424 | AD6: -0.344 | AE6: -0.272 | AF6: -0.212 | AG6: -0.166
B7: Despesas Comerciais (% Receita Líquida) | G7: 0.09 | H7: 0.089 | I7: 0.088 | J7: 0.087 | AB7: 0.36 | AC7: -0.193 | AD7: -0.103 | AE7: -0.024 | AF7: 0.039 | AG7: 0.088
B8: G&A (% Receita Líquida) | G8: 0.06 | H8: 0.059 | I8: 0.058 | J8: 0.057 | AB8: 0.38 | AC8: 0.038 | AD8: 0.138 | AE8: 0.223 | AF8: 0.29 | AG8: 0.342
B9: Outras Desp. Operacionais (% Receita Líquida) | G9: 0.02 | H9: 0.019 | I9: 0.018 | J9: 0.017 | AB9: 0.4 | AC9: 0.27 | AD9: 0.379 | AE9: 0.47 | AF9: 0.542 | AG9: 0.596
B10: Alíquota Efetiva (RET, % Receita Bruta) | G10: 0.04 | H10: 0.04 | I10: 0.04 | J10: 0.04 | AB10: 0.42 | AC10: 0.501 | AD10: 0.62 | AE10: 0.717 | AF10: 0.793 | AG10: 0.85
B11: Resultado de Equivalencia Patrimonial (% Receita Líquida) | G11: 0.018 | H11: =G11 -> 0.018 | I11: =H11 -> 0.018 | J11: =I11 -> 0.018
B12: Payout (% Lucro Líquido) | G12: =25% + Multiplos!L13 -> 0.25 | H12: =60% + Multiplos!L13 -> 0.6 | I12: =70% + Multiplos!L13 -> 0.7 | J12: =80% + Multiplos!L13 -> 0.8
B13: Minoritários (% Lucro Líq. Consolidado) | G13: 0.15 | H13: 0.15 | I13: =H13 -> 0.15 | J13: =I13 -> 0.15
B14: IR / CS (% da Receita Líquida) | G14: 0.021 | H14: =G14 -> 0.021 | I14: =H14 -> 0.021 | J14: =I14 -> 0.021
A15: . | B15: Demonstração de Resultados (DRE)
B17: (=) Receita Bruta
B18: (−) Deduções (PIS/COFINS/RET)
B19: (=) Receita Líquida | C19: ='Inputs - DRE'!R5 -> 2162616 | D19: ='Inputs - DRE'!M5 -> 2355183 | E19: ='Inputs - DRE'!H5 -> 3348470 | F19: ='Inputs - DRE'!C5 -> 4343008 | G19: ='Buildup da Receita'!AE40*1000 -> 5465102.8 | H19: ='Buildup da Receita'!AK40*1000 -> 6499946.9 | I19: ='Buildup da Receita'!AQ40*1000 -> 7256210.6 | J19: ='Buildup da Receita'!AW40*1000 -> 7715735.9
B20: (−) Custos de Imóveis Vendidos (CMV) | C20: ='Inputs - DRE'!R6 -> -1428891 | D20: ='Inputs - DRE'!M6 -> -1550208 | E20: ='Inputs - DRE'!H6 -> -2130127 | F20: ='Inputs - DRE'!C6 -> -2620591 | G20: =-G19*(1-G6) -> -3279061.7 | H20: =-H19*(1-H6) -> -3964967.6 | I20: =-I19*(1-I6) -> -4462569.5 | J20: =-J19*(1-J6) -> -4745177.6
B21: (=) Lucro Bruto | C21: =C19+C20 -> 733725 | D21: =D19+D20 -> 804975 | E21: =E19+E20 -> 1218343 | F21: =F19+F20 -> 1722417 | G21: =G19+G20 -> 2186041.1 | H21: =H19+H20 -> 2534979.3 | I21: =I19+I20 -> 2793641.1 | J21: =J19+J20 -> 2970558.3
B22: Margem Bruta (%) | C22: =C21/C19 -> 0.3392766 | D22: =D21/D19 -> 0.34178873 | E22: =E21/E19 -> 0.36385065 | F22: =F21/F19 -> 0.3965954 | G22: =G6 -> 0.4 | H22: =H6 -> 0.39 | I22: =I6 -> 0.385 | J22: =J6 -> 0.385
B24: (−) Despesas Comerciais | C24: ='Inputs - DRE'!R9 -> -203082 | D24: ='Inputs - DRE'!M9 -> -202241.82 | E24: ='Inputs - DRE'!H9 -> -289706 | F24: ='Inputs - DRE'!C9 -> -408037 | G24: =-G7*G19 -> -491859.25 | H24: =-H7*H19 -> -578495.27 | I24: =-I7*I19 -> -638546.54 | J24: =-J7*J19 -> -671269.02
B25: (−) Despesas Gerais e Administrativas (G&A) | C25: ='Inputs - DRE'!R8 -> -151631 | D25: ='Inputs - DRE'!M8 -> -174709.76 | E25: ='Inputs - DRE'!H8 -> -210307 | F25: ='Inputs - DRE'!C8 -> -254781 | G25: =-G8*G19 -> -327906.17 | H25: =-H8*H19 -> -383496.87 | I25: =-I8*I19 -> -420860.22 | J25: =-J8*J19 -> -439796.95
B26: (+/−) Outras Receitas/Despesas Operacionais | C26: ='Inputs - DRE'!R11 -> -25357 | D26: ='Inputs - DRE'!M11 -> -58989.301 | E26: ='Inputs - DRE'!H11 -> -49879 | F26: ='Inputs - DRE'!C11 -> -119095 | G26: =-G9*G19 -> -109302.06 | H26: =-H9*H19 -> -123498.99 | I26: =-I9*I19 -> -130611.79 | J26: =-J9*J19 -> -131167.51
B27: (+) Resultado de Equivalência Patrimonial | C27: ='Inputs - DRE'!R10 -> 21758 | D27: ='Inputs - DRE'!M10 -> 53700.914 | E27: ='Inputs - DRE'!H10 -> 86528 | F27: ='Inputs - DRE'!C10 -> 62631 | G27: =G11*G19 -> 98371.85 | H27: =H11*H19 -> 116999.04 | I27: =I11*I19 -> 130611.79 | J27: =J11*J19 -> 138883.25
B28: (-) Depreciação | G28: =G199 -> -105429.43 | H28: =H199 -> -105337.76 | I28: =I199 -> -113356.13 | J28: =J199 -> -124024.71
B29: (=) EBIT Ex - Depreciação | C29: =C27+C26+C25+C24+C21 -> 375413 | D29: =D27+D26+D25+D24+D21 -> 422735.03 | E29: =E27+E26+E25+E24+E21 -> 754979 | F29: =F27+F26+F25+F24+F21 -> 1003135 | G29: =G27+G26+G25+G24+G21 -> 1355345.5 | H29: =H27+H26+H25+H24+H21 -> 1566487.2 | I29: =I27+I26+I25+I24+I21 -> 1734234.3 | J29: =J27+J26+J25+J24+J21 -> 1867208.1
B30: (=) EBIT | C30: =C21+C27+C26+C25+C24 -> 375413 | D30: =D21+D27+D26+D25+D24 -> 422735.03 | E30: =E21+E27+E26+E25+E24 -> 754979 | F30: =F21+F27+F26+F25+F24 -> 1003135 | G30: =G21+G27+G26+G25+G24+G28 -> 1249916.1 | H30: =H21+H27+H26+H25+H24+H28 -> 1461149.4 | I30: =I21+I27+I26+I25+I24+I28 -> 1620878.2 | J30: =J21+J27+J26+J25+J24+J28 -> 1743183.4
B31: Margem EBIT (%) | C31: =C30/C19 -> 0.17359208 | D31: =D30/D19 -> 0.17949137 | E31: =E30/E19 -> 0.22546984 | F31: =F30/F19 -> 0.23097701 | G31: =G30/G19 -> 0.22870861 | H31: =H30/H19 -> 0.22479406 | I31: =I30/I19 -> 0.22337805 | J31: =J30/J19 -> 0.22592574
B33: (+/−) Resultado Financeiro | C33: =SUM('Inputs - DRE'!R12,'Inputs - DRE'!R13) -> -73878 | D33: =SUM('Inputs - DRE'!M12,'Inputs - DRE'!M13) -> 14123.897 | E33: =SUM('Inputs - DRE'!H12,'Inputs - DRE'!H13) -> 37319 | F33: =SUM('Inputs - DRE'!C12,'Inputs - DRE'!C13) -> 75360 | G33: =G191+G206 -> -50746.381 | H33: =H191+H206 -> 25976.481 | I33: =I191+I206 -> 28971.062 | J33: =J191+J206 -> 47379.948
B35: (=) EBT | C35: =C30+C33 -> 301535 | D35: =D30+D33 -> 436858.93 | E35: =E30+E33 -> 792298 | F35: =F30+F33 -> 1078495 | G35: =G30+G33 -> 1199169.7 | H35: =H30+H33 -> 1487125.9 | I35: =I30+I33 -> 1649849.3 | J35: =J30+J33 -> 1790563.3
B36: (-) IR / CS | C36: ='Inputs - DRE'!R15 -> -45846 | D36: ='Inputs - DRE'!M15 -> -49981.552 | E36: ='Inputs - DRE'!H15 -> -64630.454 | F36: ='Inputs - DRE'!C15 -> -98803 | G36: =-G14*G19 -> -114767.16 | H36: =-H14*H19 -> -136498.88 | I36: =-I14*I19 -> -152380.42 | J36: =-J14*J19 -> -162030.45
B37: (=) Lucro Líquido Antes de SPEs | C37: =C35+C36 -> 255689 | D37: =D35+D36 -> 386877.38 | E37: =E35+E36 -> 727667.55 | F37: =F35+F36 -> 979692 | G37: =G35+G36 -> 1084402.5 | H37: =H35+H36 -> 1350627 | I37: =I35+I36 -> 1497468.9 | J37: =J35+J36 -> 1628532.9
B38: (−) Participação de Minoritários | C38: ='Inputs - DRE'!R17 -> -65669 | D38: ='Inputs - DRE'!M17 -> -55317.086 | E38: ='Inputs - DRE'!H17 -> -89290.163 | F38: ='Inputs - DRE'!C17 -> -190350 | G38: =-G13*G37 -> -162660.38 | H38: =-H13*H37 -> -202594.05 | I38: =-I13*I37 -> -224620.33 | J38: =-J13*J37 -> -244279.93
B39: (=) Lucro Líquido | C39: =C37+C38 -> 190020 | D39: =D37+D38 -> 331560.3 | E39: =E37+E38 -> 638377.38 | F39: =F37+F38 -> 789342 | G39: =G37+G38 -> 921742.14 | H39: =H37+H38 -> 1148033 | I39: =I37+I38 -> 1272848.5 | J39: =J37+J38 -> 1384252.9
B40: Margem Líquida (%) | C40: =C39/C19 -> 0.087865807 | D40: =D39/D19 -> 0.14077899 | E40: =E39/E19 -> 0.19064748 | F40: =F39/F19 -> 0.18175007 | G40: =G39/G19 -> 0.16865962 | H40: =H39/H19 -> 0.1766219 | I40: =I39/I19 -> 0.17541505 | J40: =J39/J19 -> 0.17940647
B42: # Ações em Circulação (mn) | C42: 519000 | D42: =C42 -> 519000 | E42: =D42 -> 519000 | F42: =E42 -> 519000 | G42: =F42 -> 519000 | H42: =G42 -> 519000 | I42: =H42 -> 519000 | J42: =I42 -> 519000
B43: Lucro por Ação - LPA (R$)
A47: . | B47: Balanço Patrimonial
A49: . | B49: ATIVO CIRCULANTE | C49: 2777103 | D49: 3583354.8 | E49: 4571386 | F49: 6128834 | G49: =SUM(G50:G59) -> 6978965.7 | H49: =SUM(H50:H59) -> 7701069.7 | I49: =SUM(I50:I59) -> 8607141.9 | J49: =SUM(J50:J59) -> 9096853.5
...

Sheet FCFF
C1: 2026E | D1: 2027E | E1: 2028E | F1: 2029E | G1: Perpetuidade
A2: . | B2: Free Cash Flow to Firm (FCFF)
B3: NOPAT = EBIT × (1 - T) | C3: =Modelo!G30*(1-FCFF!$C$36) -> 1137423.6 | D3: =Modelo!H30*(1-FCFF!$C$36) -> 1329646 | E3: =Modelo!I30*(1-FCFF!$C$36) -> 1474999.2 | F3: =Modelo!J30*(1-FCFF!$C$36) -> 1586296.9
B4: (+) Depreciação e Amortização | C4: =-Modelo!G28 -> 105429.43 | D4: =-Modelo!H28 -> 105337.76 | E4: =-Modelo!I28 -> 113356.13 | F4: =-Modelo!J28 -> 124024.71
B5: (+/−) Δ Working Capital | C5: =-Modelo!G145 -> -381683.12 | D5: =-Modelo!H145 -> -685863.79 | E5: =-Modelo!I145 -> -501025.24 | F5: =-Modelo!J145 -> -295046.86
B6: (−) CAPEX | C6: =-Modelo!G198 -> -105203.23 | D6: =-Modelo!H198 -> -125123.98 | E6: =-Modelo!I198 -> -139682.05 | F6: =-Modelo!J198 -> -148527.92
B7: (=) Free Cash Flow to Firm (FCFF) | C7: =C3+C4+C5+C6 -> 755966.69 | D7: =D3+D4+D5+D6 -> 623995.98 | E7: =E3+E4+E5+E6 -> 947648.01 | F7: =F3+F4+F5+F6 -> 1266746.8 | G7: =F7*(1+C39)/(C37-C39) -> 11709259
B9: Valor Presente do FCFF | C9: =C7/(1+$C$37)^C10 -> 655930.32 | D9: =D7/(1+$C$37)^D10 -> 469777.14 | E9: =E7/(1+$C$37)^E10 -> 619030.69 | F9: =F7/(1+$C$37)^F10 -> 717976.11 | G9: =G7/(1+C37)^4 -> 6636660.5
B10: t (anos) | C10: 1 | D10: 2 | E10: 3 | F10: 4
A12: . | B12: Valuation
B13: PV Cash Flow Explícito (2026-2029) | C13: =SUM(C9:F9) -> 2462714.3
B14: PV Perpetuidade | C14: =G9 -> 6636660.5
B15: (=) Enterprise Value (EV) | C15: =C14+C13 -> 9099374.8
B16: (−) Dívida Líquida (4T25) | C16: =-(Modelo!F79+Modelo!F97-Modelo!F50-Modelo!F51-Modelo!F63) -> -345188
B17: (=) Equity Value | C17: =C15+C16 -> 8754186.8
B18: # Ações em Circulação (mn) | C18: 519000
B19: Target Price (R$/ação) | C19: =C17/C18 -> 16.867412
B20: Current Price (R$/ação) | C20: 13.3
B21: Upside % | C21: =(C19-C20)/C20 -> 0.26822646
G22: =C21 -> 0.26822646 | H22: 0.1725 | I22: 0.1625 | J22: 0.1525 | K22: 0.1425 | L22: 0.1325
A23: . | B23: Cost of Equity (CAPM) | G23: 0.03 | H23: -0.0067297636 | I23: 0.08008992 | J23: 0.18137378 | K23: 0.30099215 | L23: 0.44432646
B24: Beta (5Y Mensal) | C24: 1.1 | G24: 0.035 | H24: 0.022322816 | I24: 0.11466283 | J24: 0.22301698 | K24: 0.35186794 | L24: 0.50753819
B25: Risk-Free Rate (USA 10Y Treasury) | C25: 0.045 | G25: 0.04 | H25: 0.053568044 | I25: 0.15205801 | J25: 0.26836179 | K25: 0.40770723 | L25: 0.57758363
B26: Equity Risk Premium (USA mature) | C26: 0.045 | G26: 0.045 | H26: 0.087263877 | I26: 0.19263576 | J26: 0.31792473 | K26: 0.46927362 | L26: 0.65563426
B27: CRP Brasil (Damodaran) | C27: 0.0324 | G27: 0.05 | H27: 0.12371039 | I27: 0.23682042 | J27: 0.37232308 | K27: 0.53749584 | L27: 0.74314557
B28: Devaluation Risk (Inflação BR-USA) | C28: 0.02
B29: Cost of Equity (Ke) | C29: =C25+C24*C26+C27+C28+2% -> 0.1669
A31: . | B31: WACC
B32: Cost of Debt (Kd) | C32: 0.14 | G32: =C21 -> 0.26822646 | H32: 0.36 | I32: 0.38 | J32: 0.4 | K32: 0.42 | L32: 0.44
B33: D / (D+E) | C33: ='Inputs - BP'!H137/('Inputs - BP'!H137 +FCFF!C40) -> 0.36428672 | G33: 0.16 | H33: -0.129 | I33: 0.035 | J33: 0.199 | K33: 0.254 | L33: 0.294
B34: E / (D+E) | C34: =1-C33 -> 0.63571328 | G34: 0.18 | H34: -0.1 | I34: 0.068 | J34: 0.236 | K34: 0.264 | L34: 0.304
B35: Tax Rate 2 | C35: 0.25
B36: Tax Rate | C36: 0.09 | G36: 0.2 | H36: -0.075 | I36: 0.096 | J36: 0.268 | K36: 0.272 | L36: 0.312
B37: WACC (nominal em R$) | C37: =C29*C34+C32*C33*(1-C36) -> 0.15251067 | G37: 0.22 | H37: -0.053 | I37: 0.12 | J37: 0.294 | K37: 0.279 | L37: 0.319
G38: 0.24 | H38: -0.035 | I38: 0.14 | J38: 0.316 | K38: 0.285 | L38: 0.325
A39: ● | B39: Perpetuity Growth (g) | C39: 0.04
B40: Current Mkt Cap (R$ mn) | C40: 6902700

Sheet Multiplos
B2: R$ '000 | C2: 2026E | D2: 2027E | E2: 2028E | F2: 2029E
B4: Lucro Líquido | C4: =Modelo!G39 -> 921742.14 | D4: =Modelo!H39 -> 1148033 | E4: =Modelo!I39 -> 1272848.5 | F4: =Modelo!J39 -> 1384252.9
B7: (-) Valor de Entrada | C7: =-FCFF!C40 -> -6902700
B8: (+) Dividendos | C8: =-Modelo!G133 -> 230435.53 | D8: =-Modelo!H133 -> 688819.78 | E8: =-Modelo!I133 -> 890993.97 | F8: =-Modelo!J133 -> 1107402.4
B9: (+) Valor de Saída | D9: =IF(C14=2027,C18*E4,0) -> 0 | E9: =IF(C14=2028,C18*F4,0) -> 0 | F9: =IF(C14=2029,F4*(1+FCFF!C39)*C18,0) -> 8637738.3
B11: Fluxo de Caixa | C11: =C7+C8 -> -6672264.5 | D11: =D7+D8+D9 -> 688819.78 | E11: =E7+E8+E9 -> 890993.97 | F11: =F7+F8+F9 -> 9745140.7
K13: Delta Payout | L13: 0
B14: Ano de Saída | C14: 2029
B16: Múltiplo de Entrada | C16: =-C7/D4 -> 6.0126322
I17: =C20 -> 0.21042681 | J17: 3 | K17: 4 | L17: 6 | M17: 7 | N17: 8
B18: Múltiplo de Saída | C18: 6 | I18: 1184253 | J18: -0.01664997 | K18: 0.050247373 | L18: 0.16175042 | M18: 0.20981471 | N18: 0.25412479
I19: 1284253 | J19: 0.001227837 | K19: 0.070878801 | L19: 0.18662106 | M19: 0.23641274 | N19: 0.28227397
B20: TIR | C20: =IF(C14=2027,IRR(C11:D11),IF(C14=2028,IRR(C11:E11),IF(C14=2029,IRR(C11:F11),0))) -> 0.21042681 | I20: 1384253 | J20: 0.01843626 | K20: 0.090686282 | L20: 0.21042683 | M20: 0.26184775 | N20: 0.30917226
I21: 1484253 | J21: 0.035035164 | K21: 0.10974805 | L21: 0.23327553 | M21: 0.28623977 | N21: 0.33495067
B22: MOIC | C22: =(SUM(C8:F8)+F9)/-C7 -> 1.6740391 | I22: 1584253 | J22: 0.05107625 | K22: 0.12813104 | L22: 0.25525845 | M22: 0.30969009 | N22: 0.3597195
I26: =C20 -> 0.21042681 | J26: 4 | K26: 5 | L26: 6 | M26: 7 | N26: 8
I27: 2027 | J27: -0.13369533 | K27: 0.05707177 | L27: 0.24783887 | M27: 0.43860596 | N27: 0.62937306
I28: 2028 | J28: 0.034499803 | K28: 0.13490947 | L28: 0.22677083 | M28: 0.31195444 | N28: 0.3917343
I29: 2029 | J29: 0.09068627 | K29: 0.15388 | L29: 0.21042681 | M29: 0.26184774 | N29: 0.30917225
I35: =C20 -> 0.21042681 | J35: 4 | K35: 5 | L35: 6 | M35: 7 | N35: 8
I36: -0.1 | J36: 0.079395109 | K36: 0.14432988 | L36: 0.20227598 | M36: 0.25486353 | N36: 0.30318707
I37: -0.05 | J37: 0.085064251 | K37: 0.14912252 | L37: 0.20636516 | M37: 0.2583668 | N37: 0.30618897
I38: 0 | J38: 0.09068627 | K38: 0.15388 | L38: 0.21042681 | M38: 0.26184774 | N38: 0.30917225
I39: 0.05 | J39: 0.096262288 | K39: 0.15860315 | L39: 0.21446162 | M39: 0.26530694 | N39: 0.31213743
I40: 0.1 | J40: 0.10179342 | K40: 0.16329281 | L40: 0.21847029 | M40: 0.26874501 | N40: 0.31508507

Sheet Buildup da Receita
B1: [R$ milhões] | C1: 2022A | I1: 2023A | O1: 2024A | U1: 2025A | AA1: 2026E | AG1: 2027E | AM1: 2028E | AS1: 2029E
C2: 1T22 | D2: 2T22 | E2: 3T22 | F2: 4T22 | G2: Total 2022 | I2: 1T23 | J2: 2T23 | K2: 3T23 | L2: 4T23 | M2: Total 2023 | O2: 1T24 | P2: 2T24 | Q2: 3T24 | R2: 4T24 | S2: Total 2024 | U2: 1T25 | V2: 2T25 | W2: 3T25 | X2: 4T25 | Y2: Total 2025 | AA2: 1T26 | AB2: 2T26 | AC2: 3T26 | AD2: 4T26 | AE2: Total 2026 | AG2: 1T27 | AH2: 2T27 | AI2: 3T27 | AJ2: 4T27 | AK2: Total 2027 | AM2: 1T28 | AN2: 2T28 | AO2: 3T28 | AP2: 4T28 | AQ2: Total 2028 | AS2: 1T29 | AT2: 2T29 | AU2: 3T29 | AV2: 4T29 | AW2: Total 2029
B4: BLOCO TRIMESTRAL
B6: Lançamentos | C6: 599 | D6: 790 | E6: 1189 | F6: 1057 | G6: 3635 | I6: 611 | J6: 1457 | K6: 1399 | L6: 1390 | M6: 4857 | O6: 896 | P6: 1361 | Q6: 1664 | R6: 1562 | S6: 5483 | U6: 901 | V6: 1904 | W6: 2152 | X6: 1901 | Y6: 6858 | AA6: =$AE$34*$AE$30 -> 991.25532 | AB6: =$AE$34*$AE$31 -> 2094.1589 | AC6: =$AE$34*$AE$32 -> 2367.2444 | AD6: =$AE$34*$AE$33 -> 2091.1414 | AE6: =SUM(AA6:AD6) -> 7543.8 | AG6: =$AK$34*$AK$30 -> 1050.7306 | AH6: =$AK$34*$AK$31 -> 2219.8084 | AI6: =$AK$34*$AK$32 -> 2509.2791 | AJ6: =$AK$34*$AK$33 -> 2216.6098 | AK6: =SUM(AG6:AJ6) -> 7996.428 | AM6: =$AQ$34*$AQ$30 -> 1103.2672 | AN6: =$AQ$34*$AQ$31 -> 2330.7988 | AO6: =$AQ$34*$AQ$32 -> 2634.7431 | AP6: =$AQ$34*$AQ$33 -> 2327.4403 | AQ6: =SUM(AM6:AP6) -> 8396.2494 | AS6: =$AW$34*$AW$30 -> 1158.4305 | AT6: =$AW$34*$AW$31 -> 2447.3388 | AU6: =$AW$34*$AW$32 -> 2766.4802 | AV6: =$AW$34*$AW$33 -> 2443.8124 | AW6: =SUM(AS6:AV6) -> 8816.0619
B7: VSO Lançamento | C7: 0.32 | D7: 0.32 | E7: 0.32 | F7: 0.32 | I7: 0.32 | J7: 0.32 | K7: 0.32 | L7: 0.32 | O7: 0.32 | P7: 0.32 | Q7: 0.32 | R7: 0.32 | U7: 0.32 | V7: 0.32 | W7: 0.32 | X7: 0.32 | AA7: =$AE$25 -> 0.3 | AB7: =$AE$25 -> 0.3 | AC7: =$AE$25 -> 0.3 | AD7: =$AE$25 -> 0.3 | AG7: =$AK$25 -> 0.3 | AH7: =$AK$25 -> 0.3 | AI7: =$AK$25 -> 0.3 | AJ7: =$AK$25 -> 0.3 | AM7: =$AQ$25 -> 0.3 | AN7: =$AQ$25 -> 0.3 | AO7: =$AQ$25 -> 0.3 | AP7: =$AQ$25 -> 0.3 | AS7: =$AW$25 -> 0.3 | AT7: =$AW$25 -> 0.3 | AU7: =$AW$25 -> 0.3 | AV7: =$AW$25 -> 0.3
B8: Venda de Lançamento | C8: 191.68 | D8: 252.8 | E8: 380.48 | F8: 338.24 | G8: 1163.2 | I8: 195.52 | J8: 466.24 | K8: 447.68 | L8: 444.8 | M8: 1554.24 | O8: 286.72 | P8: 435.52 | Q8: 532.48 | R8: 499.84 | S8: 1754.56 | U8: 288.32 | V8: 609.28 | W8: 688.64 | X8: 608.32 | Y8: 2194.56 | AA8: =AA7*AA6 -> 297.3766 | AB8: =AB7*AB6 -> 628.24766 | AC8: =AC7*AC6 -> 710.17333 | AD8: =AD7*AD6 -> 627.34241 | AE8: =SUM(AA8:AD8) -> 2263.14 | AG8: =AG7*AG6 -> 315.21919 | AH8: =AH7*AH6 -> 665.94252 | AI8: =AI7*AI6 -> 752.78373 | AJ8: =AJ7*AJ6 -> 664.98295 | AK8: =SUM(AG8:AJ8) -> 2398.9284 | AM8: =AM7*AM6 -> 330.98015 | AN8: =AN7*AN6 -> 699.23965 | AO8: =AO7*AO6 -> 790.42292 | AP8: =AP7*AP6 -> 698.2321 | AQ8: =SUM(AM8:AP8) -> 2518.8748 | AS8: =AS7*AS6 -> 347.52916 | AT8: =AT7*AT6 -> 734.20163 | AU8: =AU7*AU6 -> 829.94406 | AV8: =AV7*AV6 -> 733.14371 | AW8: =SUM(AS8:AV8) -> 2644.8186
B10: Estoque Inicial | C10: 3257 | D10: 3310 | E10: 3266 | F10: 3693 | G10: 3257 | I10: 4203 | J10: 4043 | K10: 4583 | L10: 5021 | M10: 4203 | O10: 5146 | P10: 4778 | Q10: 4592 | R10: 4491 | S10: 5146 | U10: 4787 | V10: 4458 | W10: 4716 | X10: 5296 | Y10: 4787 | AA10: =X22 -> 5696 | AB10: =AA22 -> 5250.6787 | AC10: =AB22 -> 5666.4542 | AD10: =AC22 -> 6190.2345 | AE10: =AA10 -> 5696 | AG10: =AD22 -> 6415.9865 | AH10: =AG22 -> 5868.3007 | AI10: =AH22 -> 6248.5064 | AJ10: =AI22 -> 6755.3005 | AK10: =AG10 -> 6415.9865 | AM10: =AJ22 -> 6955.8673 | AN10: =AM22 -> 6336.9809 | AO10: =AN22 -> 6701.1439 | AP10: =AO22 -> 7205.2352 | AQ10: =AM10 -> 6955.8673 | AS10: =AP22 -> 7393.3964 | AT10: =AS22 -> 6799.5525 | AU10: =AT22 -> 7220.7746 | AV10: =AU22 -> 7785.3636 | AW10: =AS10 -> 7393.3964
B11: VSO Estoque | C11: 0.21 | D11: 0.21 | E11: 0.21 | F11: 0.21 | I11: 0.21 | J11: 0.21 | K11: 0.21 | L11: 0.21 | O11: 0.21 | P11: 0.21 | Q11: 0.21 | R11: 0.21 | U11: 0.21 | V11: 0.21 | W11: 0.21 | X11: 0.21 | AA11: =$AE$26 -> 0.2 | AB11: =$AE$26 -> 0.2 | AC11: =$AE$26 -> 0.2 | AD11: =$AE$26 -> 0.2 | AG11: =$AK$26 -> 0.2 | AH11: =$AK$26 -> 0.2 | AI11: =$AK$26 -> 0.2 | AJ11: =$AK$26 -> 0.2 | AM11: =$AQ$26 -> 0.2 | AN11: =$AQ$26 -> 0.2 | AO11: =$AQ$26 -> 0.2 | AP11: =$AQ$26 -> 0.2 | AS11: =$AW$26 -> 0.19 | AT11: =$AW$26 -> 0.19 | AU11: =$AW$26 -> 0.19 | AV11: =$AW$26 -> 0.19
B12: Venda de Estoque | C12: 683.97 | D12: 695.1 | E12: 685.86 | F12: 775.53 | G12: 2840.46 | I12: 882.63 | J12: 849.03 | K12: 962.43 | L12: 1054.41 | M12: 3748.5 | O12: 1080.66 | P12: 1003.38 | Q12: 964.32 | R12: 943.11 | S12: 3991.47 | U12: 1005.27 | V12: 936.18 | W12: 990.36 | X12: 1112.16 | Y12: 4043.97 | AA12: =AA11*AA10 -> 1139.2 | AB12: =AB11*AB10 -> 1050.1357 | AC12: =AC11*AC10 -> 1133.2908 | AD12: =AD11*AD10 -> 1238.0469 | AE12: =SUM(AA12:AD12) -> 4560.6735 | AG12: =AG11*AG10 -> 1283.1973 | AH12: =AH11*AH10 -> 1173.6601 | AI12: =AI11*AI10 -> 1249.7013 | AJ12: =AJ11*AJ10 -> 1351.0601 | AK12: =SUM(AG12:AJ12) -> 5057.6188 | AM12: =AM11*AM10 -> 1391.1735 | AN12: =AN11*AN10 -> 1267.3962 | AO12: =AO11*AO10 -> 1340.2288 | AP12: =AP11*AP10 -> 1441.047 | AQ12: =SUM(AM12:AP12) -> 5439.8455 | AS12: =AS11*AS10 -> 1404.7453 | AT12: =AT11*AT10 -> 1291.915 | AU12: =AU11*AU10 -> 1371.9472 | AV12: =AV11*AV10 -> 1479.2191 | AW12: =SUM(AS12:AV12) -> 5547.8266
B13: Vendas Líquidas | C13: 622 | D13: 836 | E13: 847 | F13: 695 | G13: 3000 | I13: 803 | J13: 962 | K13: 1005 | L13: 1220 | M13: 3990 | O13: 1308 | P13: 1619 | Q13: 1765 | R13: 1308 | S13: 6000 | U13: 1326 | V13: 1677 | W13: 1642 | X13: 1517 | Y13: 6162 | AA13: =AA8+AA12 -> 1436.5766 | AB13: =AB8+AB12 -> 1678.3834 | AC13: =AC8+AC12 -> 1843.4642 | AD13: =AD8+AD12 -> 1865.3893 | AE13: =SUM(AA13:AD13) -> 6823.8135 | AG13: =AG8+AG12 -> 1598.4165 | AH13: =AH8+AH12 -> 1839.6027 | AI13: =AI8+AI12 -> 2002.485 | AJ13: =AJ8+AJ12 -> 2016.0431 | AK13: =SUM(AG13:AJ13) -> 7456.5472 | AM13: =AM8+AM12 -> 1722.1536 | AN13: =AN8+AN12 -> 1966.6358 | AO13: =AO8+AO12 -> 2130.6517 | AP13: =AP8+AP12 -> 2139.2791 | AQ13: =SUM(AM13:AP13) -> 7958.7203 | AS13: =AS8+AS12 -> 1752.2745 | AT13: =AT8+AT12 -> 2026.1166 | AU13: =AU8+AU12 -> 2201.8912 | AV13: =AV8+AV12 -> 2212.3628 | AW13: =SUM(AS13:AV13) -> 8192.6451
B15: REF Inicial | C15: 854 | D15: 938 | E15: 1068 | F15: 1135 | G15: 854 | I15: 1071 | J15: 1119 | K15: 1084 | L15: 1333 | M15: 1071 | O15: 1708 | P15: 1926 | Q15: 2331 | R15: 2618 | S15: 1708 | U15: 2845 | V15: 3116 | W15: 3398 | X15: 3686 | Y15: 2845 | AA15: =X21 -> 3822 | AB15: =AA21 -> 4017.9813 | AC15: =AB21 -> 4402.7703 | AD15: =AC21 -> 4833.1111 | AE15: =AA15 -> 3822 | AG15: =AD21 -> 5180.7107 | AH15: =AG21 -> 5245.571 | AI15: =AH21 -> 5525.8637 | AJ15: =AI21 -> 5868.8032 | AK15: =AG15 -> 5180.7107 | AM15: =AJ21 -> 6137.3111 | AN15: =AM21 -> 6115.7121 | AO15: =AN21 -> 6330.288 | AP15: =AO21 -> 6619.8946 | AQ15: =AM15 -> 6137.3111 | AS15: =AP21 -> 6839.8207 | AT15: =AS21 -> 6725.8454 | AU15: =AT21 -> 6883.0289 | AV15: =AU21 -> 7131.6731 | AW15: =AS15 -> 6839.8207
B16: Receita de Lançamento | C16: 38.336 | D16: 50.56 | E16: 76.096 | F16: 67.648 | G16: 232.64 | I16: 39.104 | J16: 93.248 | K16: 89.536 | L16: 88.96 | M16: 310.848 | O16: 57.344 | P16: 87.104 | Q16: 106.496 | R16: 99.968 | S16: 350.912 | U16: 57.664 | V16: 121.856 | W16: 137.728 | X16: 121.664 | Y16: 438.912 | AA16: =$AE$27*AA8 -> 59.475319 | AB16: =$AE$27*AB8 -> 125.64953 | AC16: =$AE$27*AC8 -> 142.03467 | AD16: =$AE$27*AD8 -> 125.46848 | AE16: =SUM(AA16:AD16) -> 452.628 | AG16: =$AK$27*AG8 -> 63.043838 | AH16: =$AK$27*AH8 -> 133.1885 | AI16: =$AK$27*AI8 -> 150.55675 | AJ16: =$AK$27*AJ8 -> 132.99659 | AK16: =SUM(AG16:AJ16) -> 479.78568 | AM16: =$AQ$27*AM8 -> 66.19603 | AN16: =$AQ$27*AN8 -> 139.84793 | AO16: =$AQ$27*AO8 -> 158.08458 | AP16: =$AQ$27*AP8 -> 139.64642 | AQ16: =SUM(AM16:AP16) -> 503.77496 | AS16: =$AW$27*AS8 -> 69.505832 | AT16: =$AW$27*AT8 -> 146.84033 | AU16: =$AW$27*AU8 -> 165.98881 | AV16: =$AW$27*AV8 -> 146.62874 | AW16: =SUM(AS16:AV16) -> 528.96371
B17: Receita de Estoque | C17: 341.985 | D17: 347.55 | E17: 342.93 | F17: 387.765 | G17: 1420.23 | I17: 441.315 | J17: 424.515 | K17: 481.215 | L17: 527.205 | M17: 1874.25 | O17: 540.33 | P17: 501.69 | Q17: 482.16 | R17: 471.555 | S17: 1995.735 | U17: 502.635 | V17: 468.09 | W17: 495.18 | X17: 556.08 | Y17: 2021.985 | AA17: =$AE$28*AA12 -> 569.6 | AB17: =$AE$28*AB12 -> 525.06787 | AC17: =$AE$28*AC12 -> 566.64542 | AD17: =$AE$28*AD12 -> 619.02345 | AE17: =SUM(AA17:AD17) -> 2280.3367 | AG17: =$AK$28*AG12 -> 641.59865 | AH17: =$AK$28*AH12 -> 586.83007 | AI17: =$AK$28*AI12 -> 624.85064 | AJ17: =$AK$28*AJ12 -> 675.53005 | AK17: =SUM(AG17:AJ17) -> 2528.8094 | AM17: =$AQ$28*AM12 -> 695.58673 | AN17: =$AQ$28*AN12 -> 633.69809 | AO17: =$AQ$28*AO12 -> 670.11439 | AP17: =$AQ$28*AP12 -> 720.52352 | AQ17: =SUM(AM17:AP17) -> 2719.9227 | AS17: =$AW$28*AS12 -> 702.37266 | AT17: =$AW$28*AT12 -> 645.95749 | AU17: =$AW$28*AU12 -> 685.97359 | AV17: =$AW$28*AV12 -> 739.60954 | AW17: =SUM(AS17:AV17) -> 2773.9133
B18: Receita Evolução REF | C18: 136.64 | D18: 150.08 | E18: 170.88 | F18: 181.6 | G18: 639.2 | I18: 171.36 | J18: 179.04 | K18: 173.44 | L18: 213.28 | M18: 737.12 | O18: 273.28 | P18: 308.16 | Q18: 372.96 | R18: 418.88 | S18: 1373.28 | U18: 455.2 | V18: 498.56 | W18: 543.68 | X18: 589.76 | Y18: 2087.2 | AA18: =$AE$29*AA15 -> 611.52 | AB18: =$AE$29*AB15 -> 642.877 | AC18: =$AE$29*AC15 -> 704.44324 | AD18: =$AE$29*AD15 -> 773.29778 | AE18: =SUM(AA18:AD18) -> 2732.138 | AG18: =$AK$29*AG15 -> 828.91371 | AH18: =$AK$29*AH15 -> 839.29136 | AI18: =$AK$29*AI15 -> 884.1382 | AJ18: =$AK$29*AJ15 -> 939.00851 | AK18: =SUM(AG18:AJ18) -> 3491.3518 | AM18: =$AQ$29*AM15 -> 981.96977 | AN18: =$AQ$29*AN15 -> 978.51394 | AO18: =$AQ$29*AO15 -> 1012.8461 | AP18: =$AQ$29*AP15 -> 1059.1831 | AQ18: =SUM(AM18:AP18) -> 4032.5129 | AS18: =$AW$29*AS15 -> 1094.3713 | AT18: =$AW$29*AT15 -> 1076.1353 | AU18: =$AW$29*AU15 -> 1101.2846 | AV18: =$AW$29*AV15 -> 1141.0677 | AW18: =SUM(AS18:AV18) -> 4412.8589
B19: Receita Total | C19: 468 | D19: 586 | E19: 574 | F19: 534 | G19: 2162 | I19: 557 | J19: 605 | K19: 558 | L19: 635 | M19: 2355 | O19: 669 | P19: 844 | Q19: 911 | R19: 924 | S19: 3348 | U19: 894 | V19: 1065 | W19: 1158 | X19: 1226 | Y19: 4343 | AA19: =AA16+AA17+AA18 -> 1240.5953 | AB19: =AB16+AB17+AB18 -> 1293.5944 | AC19: =AC16+AC17+AC18 -> 1413.1233 | AD19: =AD16+AD17+AD18 -> 1517.7897 | AE19: =SUM(AA19:AD19) -> 5465.1028 | AG19: =AG16+AG17+AG18 -> 1533.5562 | AH19: =AH16+AH17+AH18 -> 1559.3099 | AI19: =AI16+AI17+AI18 -> 1659.5456 | AJ19: =AJ16+AJ17+AJ18 -> 1747.5351 | AK19: =SUM(AG19:AJ19) -> 6499.9469 | AM19: =AM16+AM17+AM18 -> 1743.7525 | AN19: =AN16+AN17+AN18 -> 1752.06 | AO19: =AO16+AO17+AO18 -> 1841.0451 | AP19: =AP16+AP17+AP18 -> 1919.3531 | AQ19: =SUM(AM19:AP19) -> 7256.2106 | AS19: =AS16+AS17+AS18 -> 1866.2498 | AT19: =AT16+AT17+AT18 -> 1868.9331 | AU19: =AU16+AU17+AU18 -> 1953.247 | AV19: =AV16+AV17+AV18 -> 2027.306 | AW19: =SUM(AS19:AV19) -> 7715.7359
B21: REF Final | C21: 938 | D21: 1068 | E21: 1135 | F21: 1071 | G21: 1071 | I21: 1119 | J21: 1084 | K21: 1333 | L21: 1708 | M21: 1708 | O21: 1926 | P21: 2331 | Q21: 2618 | R21: 2845 | S21: 2845 | U21: 3116 | V21: 3398 | W21: 3686 | X21: 3822 | Y21: 3822 | AA21: =AA15+AA13-AA19 -> 4017.9813 | AB21: =AB15+AB13-AB19 -> 4402.7703 | AC21: =AC15+AC13-AC19 -> 4833.1111 | AD21: =AD15+AD13-AD19 -> 5180.7107 | AE21: =AD21 -> 5180.7107 | AG21: =AG15+AG13-AG19 -> 5245.571 | AH21: =AH15+AH13-AH19 -> 5525.8637 | AI21: =AI15+AI13-AI19 -> 5868.8032 | AJ21: =AJ15+AJ13-AJ19 -> 6137.3111 | AK21: =AJ21 -> 6137.3111 | AM21: =AM15+AM13-AM19 -> 6115.7121 | AN21: =AN15+AN13-AN19 -> 6330.288 | AO21: =AO15+AO13-AO19 -> 6619.8946 | AP21: =AP15+AP13-AP19 -> 6839.8207 | AQ21: =AP21 -> 6839.8207 | AS21: =AS15+AS13-AS19 -> 6725.8454 | AT21: =AT15+AT13-AT19 -> 6883.0289 | AU21: =AU15+AU13-AU19 -> 7131.6731 | AV21: =AV15+AV13-AV19 -> 7316.7299 | AW21: =AV21 -> 7316.7299
B22: Estoque Final | C22: 3310 | D22: 3266 | E22: 3693 | F22: 4203 | G22: 4203 | I22: 4043 | J22: 4583 | K22: 5021 | L22: 5146 | M22: 5146 | O22: 4778 | P22: 4592 | Q22: 4491 | R22: 4787 | S22: 4787 | U22: 4458 | V22: 4716 | W22: 5296 | X22: 5696 | Y22: 5696 | AA22: =AA10+AA6-AA13 -> 5250.6787 | AB22: =AB10+AB6-AB13 -> 5666.4542 | AC22: =AC10+AC6-AC13 -> 6190.2345 | AD22: =AD10+AD6-AD13 -> 6415.9865 | AE22: =AD22 -> 6415.9865 | AG22: =AG10+AG6-AG13 -> 5868.3007 | AH22: =AH10+AH6-AH13 -> 6248.5064 | AI22: =AI10+AI6-AI13 -> 6755.3005 | AJ22: =AJ10+AJ6-AJ13 -> 6955.8673 | AK22: =AJ22 -> 6955.8673 | AM22: =AM10+AM6-AM13 -> 6336.9809 | AN22: =AN10+AN6-AN13 -> 6701.1439 | AO22: =AO10+AO6-AO13 -> 7205.2352 | AP22: =AP10+AP6-AP13 -> 7393.3964 | AQ22: =AP22 -> 7393.3964 | AS22: =AS10+AS6-AS13 -> 6799.5525 | AT22: =AT10+AT6-AT13 -> 7220.7746 | AU22: =AU10+AU6-AU13 -> 7785.3636 | AV22: =AV10+AV6-AV13 -> 8016.8132 | AW22: =AV22 -> 8016.8132
B24: PREMISSAS
B25: VSO Lançamento (% Lançamentos) | AE25: 0.3 | AK25: 0.3 | AQ25: 0.3 | AW25: 0.3
B26: VSO Estoque (% Estoque Inicial) | AE26: 0.2 | AK26: 0.2 | AQ26: 0.2 | AW26: 0.19
B27: PoC Lançamento (% Vendas Lanç.) | AE27: 0.2 | AK27: 0.2 | AQ27: 0.2 | AW27: 0.2
B28: PoC Estoque (% Vendas Est.) | AE28: 0.5 | AK28: 0.5 | AQ28: 0.5 | AW28: 0.5
B29: Drenagem REF (% REF Inicial) | AE29: 0.16 | AK29: 0.16 | AQ29: 0.16 | AW29: 0.16
B30: % VGV no 1T | AE30: 0.1314 | AK30: 0.1314 | AQ30: 0.1314 | AW30: 0.1314
B31: % VGV no 2T | AE31: 0.2776 | AK31: 0.2776 | AQ31: 0.2776 | AW31: 0.2776
B32: % VGV no 3T | AE32: 0.3138 | AK32: 0.3138 | AQ32: 0.3138 | AW32: 0.3138
B33: % VGV no 4T | AE33: 0.2772 | AK33: 0.2772 | AQ33: 0.2772 | AW33: 0.2772
B34: VGV Anual Lançado | G34: 3636 | M34: 4857 | S34: 5484 | Y34: 6858 | AC34: 0.1 | AE34: =Y34*(1+AC34) -> 7543.8 | AK34: 7996.428 | AQ34: 8396.2494 | AW34: 8816.0619
B35: Check Sazonalidade (= 100%) | AE35: =SUM(AE30:AE33) -> 1 | AK35: =SUM(AK30:AK33) -> 1 | AQ35: =SUM(AQ30:AQ33) -> 1 | AW35: =SUM(AW30:AW33) -> 1
B37: RESUMO ANUAL
B38: VGV Lançado | G38: 3635 | M38: 4857 | S38: 5483 | Y38: 6858 | AE38: =AE6 -> 7543.8 | AK38: =AK6 -> 7996.428 | AQ38: =AQ6 -> 8396.2494 | AW38: =AW6 -> 8816.0619
B39: Vendas Líquidas | G39: 3000 | M39: 3990 | S39: 6000 | Y39: 6162 | AE39: =AE13 -> 6823.8135 | AK39: =AK13 -> 7456.5472 | AQ39: =AQ13 -> 7958.7203 | AW39: =AW13 -> 8192.6451
B40: Receita Reconhecida | G40: 2162 | M40: 2355 | S40: 3348 | Y40: 4343 | AE40: =AE19 -> 5465.1028 | AK40: =AK19 -> 6499.9469 | AQ40: =AQ19 -> 7256.2106 | AW40: =AW19 -> 7715.7359
B41: Estoque Final | G41: 4203 | M41: 5146 | S41: 4787 | Y41: 5696 | AD41: Ef | AE41: =AE22 -> 6415.9865 | AJ41: Ef | AK41: =AK22 -> 6955.8673 | AP41: Ef | AQ41: =AQ22 -> 7393.3964 | AV41: Ef | AW41: =AW22 -> 8016.8132
B42: REF Final | G42: 1071 | M42: 1708 | S42: 2845 | Y42: 3822 | AE42: =AE21 -> 5180.7107 | AK42: =AK21 -> 6137.3111 | AQ42: =AQ21 -> 6839.8207 | AW42: =AW21 -> 7316.7299

Sheet Inputs - BP
B2: DIRECIONAL ENGENHARIA S.A.
B4: BALANÇO PATRIMONIAL (MILHARES DE R$) | C4: 2025 | D4: 4T25 | E4: 3T25 | F4: 2T25 | G4: 1T25 | H4: 2024 | I4: 4T24 | J4: 3T24 | K4: 2T24 | L4: 1T24 | M4: 2023 | N4: 4T23 | O4: 3T23 | P4: 2T23 | Q4: 1T23 | R4: 2022 | S4: 2021 | T4: 2020 | U4: 2019 | V4: 2018 | W4: 2017 | X4: 2016 | Y4: 2015 | Z4: 2014 | AA4: 2013 | AB4: 2012
B5: ATIVO CIRCULANTE | C5: 6128834 | D5: 6128834 | E5: 5613159 | F5: 5250822 | G5: 4685810 | H5: 4571386 | I5: 4571386 | J5: 4331445.2 | K5: 4280991.1 | L5: 3356579.9 | M5: 3583354.8 | N5: 3583354.8 | O5: 3359245.4 | P5: 3272452.7 | Q5: 2979504.3 | R5: 2777103 | S5: 2832036 | T5: 2657226 | U5: 2333425 | V5: 2251114 | W5: 2351425 | X5: 2518272 | Y5: 2434863 | Z5: 2720652 | AA5: 2441768 | AB5: 2566313
B6: Caixa e equivalentes de caixa | C6: 1199343 | D6: 1199343 | E6: 1575523 | F6: 1251709 | G6: 837999 | H6: 792054 | I6: 792054 | J6: 858169 | K6: 649740 | L6: 445832 | M6: 633978 | N6: 633978 | O6: 813714 | P6: 637397 | Q6: 605952 | R6: 733124 | S6: 723954 | T6: 731569 | U6: 533795 | V6: 715294 | W6: 413048 | X6: 432735 | Y6: 436624 | Z6: 636110 | AA6: 489776 | AB6: 374580
B7: Aplicações financeiras | C7: 983456 | D7: 983456 | E7: 873983 | F7: 872871 | G7: 791523 | H7: 823127 | I7: 823127 | J7: 687599 | K7: 772261 | L7: 730530 | M7: 693193 | N7: 693193 | O7: 527447 | P7: 475806 | Q7: 465975 | R7: 454248 | S7: 325206 | T7: 195360 | U7: 195587 | V7: 144050 | W7: 70709 | X7: 134816 | Y7: 62541 | Z7: 29099 | AA7: 52775 | AB7: 75313
B8: Contas a receber | C8: 1438700 | D8: 1438700 | E8: 1348006 | F8: 1280505 | G8: 1106026 | H8: 992821 | I8: 992821 | J8: 844423.5 | K8: 789183.92 | L8: 634970.39 | M8: 521946.46 | N8: 521946.46 | O8: 407922.5 | P8: 399289.04 | Q8: 403426.98 | R8: 363372 | S8: 231761 | T8: 246717 | U8: 347538 | V8: 394942 | W8: 702949 | X8: 949979 | Y8: 1122388 | Z8: 1172496 | AA8: 1391817 | AB8: 1325430
B9: Estoques | C9: 2086835 | D9: 2086835 | E9: 1442734 | F9: 1497527 | G9: 1598745 | H9: 1643111 | I9: 1643111 | J9: 1570926.3 | K9: 1710111.8 | L9: 1222127.2 | M9: 1420698.9 | N9: 1420698.9 | O9: 1318928.1 | P9: 1369589.3 | Q9: 1206108 | R9: 960135 | S9: 1239177 | T9: 1270816 | U9: 1080673 | V9: 823164 | W9: 971225 | X9: 805817 | Y9: 656290 | Z9: 735011 | AA9: 396119 | AB9: 680201
B10: Terrenos disponíveis para vendas | C10: 0 | D10: 0 | E10: 0 | F10: 0 | G10: 0 | H10: 0 | I10: 0 | J10: 0 | K10: 0 | L10: 0 | M10: 0 | N10: 0 | O10: 0 | P10: 0 | Q10: 0 | R10: 0 | S10: 0 | T10: 0 | U10: 0 | V10: 0 | W10: 0 | X10: 0 | Y10: 0 | Z10: 0 | AA10: 0 | AB10: 0
B11: Crédito com partes relacionadas | C11: 92922 | D11: 92922 | E11: 80933 | F11: 75761 | G11: 65055 | H11: 71054 | I11: 71054 | J11: 110101.35 | K11: 81642.802 | L11: 71760.298 | M11: 67184.39 | N11: 67184.39 | O11: 70725.503 | P11: 74512.348 | Q11: 66674.309 | R11: 64551 | S11: 82261 | T11: 37363 | U11: 44973 | V11: 71227 | W11: 81576 | X11: 76926 | Y11: 50104 | Z11: 41949 | AA11: 37046 | AB11: 44673
B12: Tributos a recuperar | C12: 43855 | D12: 43855 | E12: 38964 | F12: 46453 | G12: 42178 | H12: 37062 | I12: 37062 | J12: 49451 | K12: 42229.628 | L12: 35185 | M12: 25753 | N12: 25753 | O12: 37992.243 | P12: 34158 | Q12: 26556 | R12: 23122 | S12: 24462 | T12: 21185 | U12: 24560 | V12: 26135 | W12: 24684 | X12: 22424 | Y12: 26814 | Z12: 23256 | AA12: 17315 | AB12: 14122
B13: Despesas comerciais a apropriar | C13: 0 | D13: 0 | E13: 0 | F13: 0 | G13: 0 | H13: 0 | I13: 0 | J13: 0 | K13: 0 | L13: 0 | M13: 0 | N13: 0 | O13: 0 | P13: 0 | Q13: 0 | R13: 0 | S13: 0 | T13: 0 | U13: 0 | V13: 0 | W13: 0 | X13: 0 | Y13: 0 | Z13: 0 | AA13: 0 | AB13: 0
B14: Contas a receber por alienação de investimentos | C14: 1718 | D14: 1718 | E14: 2744 | F14: 3774 | G14: 36303 | H14: 5833 | I14: 5833 | J14: 0 | K14: 0 | L14: 0 | M14: 0 | N14: 0 | O14: 0 | P14: 68332 | Q14: 501 | R14: 501 | S14: 17540 | T14: 50000 | U14: 22514 | V14: 2013 | W14: 4000 | X14: 34102 | Y14: 0 | Z14: 0 | AA14: 0 | AB14: 0
B15: Outros créditos | C15: 282005 | D15: 282005 | E15: 250272 | F15: 222222 | G15: 207981 | H15: 206324 | I15: 206324 | J15: 210776 | K15: 235821 | L15: 216176 | M15: 220602 | N15: 220602 | O15: 182516 | P15: 213370 | Q15: 204311 | R15: 178050 | S15: 187675 | T15: 104216 | U15: 83786 | V15: 74289 | W15: 83234 | X15: 61473 | Y15: 80102 | Z15: 82731 | AA15: 56920 | AB15: 51994
B16: ATIVO NÃO CIRCULANTE | C16: 7090801 | D16: 7090801 | E16: 6802575 | F16: 6316036 | G16: 5926440 | H16: 5496020 | I16: 5496020 | J16: 5189567.2 | K16: 4519837 | L16: 4521375.7 | M16: 3988243 | N16: 3988243 | O16: 3830456.7 | P16: 3534217.6 | Q16: 3502521.6 | R16: 3712312 | S16: 2823260 | T16: 2435058 | U16: 2321291 | V16: 2400571 | W16: 1790339 | X16: 1571495 | Y16: 1452589 | Z16: 1234868 | AA16: 991888 | AB16: 615561
B17: Realizável a longo prazo | C17: 6673444 | D17: 6673444 | E17: 6390858 | F17: 5885790 | G17: 5496068 | H17: 5028708 | I17: 5028708 | J17: 4765579.6 | K17: 4108832 | L17: 4133368.7 | M17: 3671816 | N17: 3671816 | O17: 3514699.7 | P17: 3236455.6 | Q17: 3207918.3 | R17: 3407532 | S17: 2587211 | T17: 2258264 | U17: 2162619 | V17: 2265702 | W17: 1682866 | X17: 1447635 | Y17: 1324998 | Z17: 1085627 | AA17: 852001 | AB17: 529143
B18: Aplicações financeiras | C18: 230360 | D18: 230360 | E18: 168215 | F18: 149823 | G18: 102698 | H18: 99714 | I18: 99714 | J18: 54841.215 | K18: 54200
B19: Contas a receber | C19: 1389073 | D19: 1389073 | E19: 1271939 | F19: 1104148 | G19: 987445 | H19: 846706 | I19: 846706 | J19: 770586.48 | K19: 658009.96 | L19: 574103.74 | M19: 464034.95 | N19: 464034.95 | O19: 412750.7 | P19: 340819.6 | Q19: 334608.5 | R19: 314813 | S19: 244585 | T19: 128727 | U19: 96579 | V19: 121262 | W19: 132436 | X19: 138364 | Y19: 152137 | Z19: 240735 | AA19: 180454 | AB19: 138458
B20: Estoque | C20: 4864673 | D20: 4864673 | E20: 4761035 | F20: 4416854 | G20: 4208796 | H20: 3888979 | I20: 3888979 | J20: 3758232.6 | K20: 3210466 | L20: 3378229 | M20: 3041218 | N20: 3041218 | O20: 2971545 | P20: 2774269 | Q20: 2777860.4 | R20: 3018121 | S20: 2303436 | T20: 2071074 | U20: 2008992 | V20: 2090294 | W20: 1516643 | X20: 1276593 | Y20: 1134083 | Z20: 805869 | AA20: 615178 | AB20: 259356
B21: Depósitos judiciais | C21: 24277 | D21: 24277 | E21: 23484 | F21: 23959 | G21: 22544 | H21: 21555 | I21: 21555 | J21: 21719.038 | K21: 21046 | L21: 18973 | M21: 18111 | N21: 18111 | O21: 17739 | P21: 17832 | Q21: 17601.353 | R21: 17367 | S21: 16097 | T21: 15928 | U21: 16472 | V21: 15143 | W21: 18128 | X21: 0 | Y21: 0 | Z21: 0 | AA21: 0 | AB21: 0
B22: Crédito com partes relacionadas | C22: 0 | D22: 0 | E22: 0 | F22: 0 | G22: 0 | H22: 0 | I22: 0 | J22: 0 | K22: 0 | L22: 0 | M22: 0 | N22: 0 | O22: 0 | P22: 0 | Q22: 0 | R22: 0 | S22: 1636 | T22: 1636 | U22: 0 | V22: 649 | W22: 5400 | X22: 8089 | Y22: 13249 | Z22: 15910 | AA22: 20489 | AB22: 65801
B23: Tributos a recuperar | C23: 11059 | D23: 11059 | E23: 9461 | F23: 9574 | G23: 10363 | H23: 20611 | I23: 20611 | J23: 11151.789 | K23: 15973 | L23: 25156 | M23: 27548 | N23: 27548 | O23: 6526 | P23: 6526 | Q23: 6526 | R23: 6440 | S23: 0 | T23: 0 | U23: 0 | V23: 0 | W23: 0 | X23: 0 | Y23: 0 | Z23: 0 | AA23: 0 | AB23: 0
B24: Contas a receber por alienação de investimentos | C24: 5798 | D24: 5798 | E24: 5799 | F24: 5799 | G24: 7630 | H24: 7630 | I24: 7630 | J24: 7630.0841 | K24: 7630 | L24: 7630 | M24: 7630 | N24: 7630 | O24: 7630 | P24: 7129 | Q24: 7129 | R24: 7129 | S24: 0 | T24: 30685 | U24: 29722 | V24: 27985 | W24: 0 | X24: 0 | Y24: 0 | Z24: 0 | AA24: 0 | AB24: 0
B25: Outros créditos | C25: 148204 | D25: 148204 | E25: 150924 | F25: 175633 | G25: 156592 | H25: 143513 | I25: 143513 | J25: 141418.39 | K25: 141507 | L25: 129277 | M25: 113274 | N25: 113274 | O25: 98509 | P25: 89880 | Q25: 64193 | R25: 43662 | S25: 21457 | T25: 10214 | U25: 10854 | V25: 10369 | W25: 10259 | X25: 24589 | Y25: 25529 | Z25: 23113 | AA25: 35880 | AB25: 65528
B26: Permanente | C26: 417357 | D26: 417357 | E26: 411718 | F26: 430246 | G26: 430372 | H26: 467312 | I26: 467312 | J26: 423986.63 | K26: 411005 | L26: 388007 | M26: 316427 | N26: 316427 | O26: 315757 | P26: 297762 | Q26: 294604.33 | R26: 304780 | S26: 236049 | T26: 176794 | U26: 158672 | V26: 134869 | W26: 107473 | X26: 123860 | Y26: 127591 | Z26: 149241 | AA26: 139887 | AB26: 86418
B27: Investimentos | C27: 124135 | D27: 124135 | E27: 105527 | F27: 138434 | G27: 161671 | H27: 212504 | I27: 212504 | J27: 193959.47 | K27: 193645 | L27: 174396 | M27: 169375 | N27: 169375 | O27: 171047 | P27: 142090 | Q27: 133771 | R27: 143717 | S27: 117961 | T27: 73045 | U27: 48885 | V27: 64161 | W27: 49501 | X27: 50593 | Y27: 37783 | Z27: 36839 | AA27: 37154 | AB27: 24730
B28: Imobilizado | C28: 260159 | D28: 260159 | E28: 266560 | F28: 252372 | G28: 230724 | H28: 220762 | I28: 220762 | J28: 197255.89 | K28: 184863 | L28: 181833 | M28: 111474 | N28: 111474 | O28: 113832 | P28: 129142 | Q28: 136224.85 | R28: 140115 | S28: 99075 | T28: 89594 | U28: 101972 | V28: 66272 | W28: 55265 | X28: 69777 | Y28: 87086 | Z28: 109968 | AA28: 100908 | AB28: 59340
B29: Intangível | C29: 33063 | D29: 33063 | E29: 39631 | F29: 39440 | G29: 37977 | H29: 34046 | I29: 34046 | J29: 32771.273 | K29: 32497 | L29: 31778 | M29: 35578 | N29: 35578 | O29: 30878 | P29: 26530 | Q29: 24608.486 | R29: 20948 | S29: 19013 | T29: 14155 | U29: 7815 | V29: 4436 | W29: 2707 | X29: 3490 | Y29: 2722 | Z29: 2434 | AA29: 1825 | AB29: 2348
B30: Ativos de Direito de Uso | C30: 0 | D30: 0 | E30: 0 | F30: 0 | G30: 0 | H30: 0 | I30: 0 | J30: 0 | K30: 0 | L30: 0 | M30: 0 | N30: 0 | O30: 0 | P30: 0 | Q30: 0 | R30: 0 | S30: 0 | T30: 0 | U30: 0 | V30: 0 | W30: 0 | X30: 0 | Y30: 0 | Z30: 0 | AA30: 0 | AB30: 0
... B63: Capital social | C63: 1181857 | D63: 1181857 | E63: 1181857 | F63: 1181857 | G63: 1181857 | H63: 1181857 | I63: 1181857 | J63: 1181857 | K63: 1181857 | L63: 1181857 | M63: 1181857 | N63: 1181857 | O63: 1181857 | P63: 752982 | Q63: 752982 | R63: 752982 | S63: 752982 | T63: 752982 | U63: 752982 | V63: 752982 | W63: 752982 | X63: 752982 | Y63: 752982 | Z63: 702982 | AA63: 702982 | AB63: 497158
B64: Gastos com emissões de ações | C64: -21994 | D64: -21994 | E64: -21994 | F64: -21994 | G64: -21994 | H64: -21994 | I64: -21994 | J64: -21994 | K64: -21994 | L64: -21994 | M64: -21994 | N64: -21994 | O64: -20766
B65: Ações em tesouraria | C65: -22571 | D65: -22571 | E65: -8042 | F65: -4065 | G65: -4065 | H65: -9536 | I65: -9536 | J65: -2301 | K65: -2301 | L65: -2301 | M65: -7748 | N65: -7748 | O65: -7748 | P65: -7748 | Q65: -9749 | R65: -9749 | S65: -7360 | T65: -52129 | U65: -32076 | V65: -37531 | W65: -40793 | X65: -41511 | Y65: -41791 | Z65: -23118 | AA65: -28137 | AB65: -12659
B66: Reservas de capital | C66: 192734 | D66: 192734 | E66: 185857 | F66: 185540 | G66: 182348 | H66: 185178 | I66: 185178 | J66: 151029 | K66: 148551 | L66: 147249 | M66: 184240 | N66: 184240 | O66: 150757 | P66: 149179 | Q66: 149880 | R66: 148323 | S66: 150102 | T66: 193511 | U66: 194989 | V66: 196714 | W66: 193184 | X66: 189339 | Y66: 189115 | Z66: 212898 | AA66: 229111 | AB66: 445767
B67: Outorga de opção de ações | C67: 0 | D67: 0 | E67: 0 | F67: 0 | G67: 0 | H67: 0 | I67: 0 | J67: 0 | K67: 0 | L67: 0 | M67: 0 | N67: 0 | O67: 0 | P67: 0 | Q67: 0 | R67: 0 | S67: 0 | T67: 0 | U67: 0 | V67: 0 | W67: 0 | X67: 0 | Y67: 0 | Z67: 0 | AA67: 0 | AB67: 0
B68: Ajuste de avaliação patrimonial | C68: 238956 | D68: 238956 | E68: 167444 | F68: 151699 | G68: -33268 | H68: -31759 | I68: -31759 | J68: 0 | K68: 0 | L68: 0 | M68: -31760 | N68: -31760 | O68: 0 | P68: 0 | Q68: 0 | R68: 0 | S68: 0 | T68: 0 | U68: 0 | V68: 0 | W68: 0 | X68: 0 | Y68: 0 | Z68: 0 | AA68: 0 | AB68: 0
B69: Reservas de lucros | C69: 347639 | D69: 347639 | E69: 362661 | F69: 362333 | G69: 708997 | H69: 711711 | I69: 711711 | J69: 649936 | K69: 649925 | L69: 649917 | M69: 648810 | N69: 648810 | O69: 398412 | P69: 398425 | Q69: 398423 | R69: 398425 | S69: 383147 | T69: 323843 | U69: 341032 | V69: 370526 | W69: 549591 | X69: 693373 | Y69: 745235 | Z69: 711584 | AA69: 568872 | AB69: 397726
B70: Dividendos adicionais propostos | C70: 0 | D70: 0 | E70: 0 | F70: 0 | G70: 0 | H70: 0 | I70: 0 | J70: 0 | K70: 0 | L70: 0 | M70: 0 | N70: 0 | O70: 0 | P70: 0 | Q70: 0 | R70: 0 | S70: 0 | T70: 0 | U70: 0 | V70: 0 | W70: 0 | X70: 0 | Y70: 0 | Z70: 11690 | AA70: 0 | AB70: 0
B71: Lucros acumulados | C71: 0 | D71: 0 | E71: 577910 | F71: 348258 | G71: 164516 | H71: 0 | I71: 0 | J71: 100001 | K71: 296453 | L71: 150284 | M71: 0 | N71: 0 | O71: 231954 | P71: 163193 | Q71: 58754 | R71: 0 | S71: 0 | T71: 0 | U71: 0 | V71: 0 | W71: 0 | X71: 0 | Y71: 0 | Z71: 0 | AA71: 0 | AB71: 0
B72: Participantes em SCPs e SPEs | C72: 403530 | D72: 403530 | E72: 274489 | F72: 267022 | G72: 188319 | H72: 208294 | I72: 208294 | J72: 186929 | K72: 186075 | L72: 166217 | M72: 157181 | N72: 157181 | O72: 159045 | P72: 154579 | Q72: 160701 | R72: 159714 | S72: 155586 | T72: 112666 | U72: 112417 | V72: 110585 | W72: 149351 | X72: 153235 | Y72: 131944 | Z72: 119495 | AA72: 128603 | AB72: 187315
B73: TOTAL DO PASSIVO E PATRIMÔNIO LÍQUIDO | C73: 13219635 | D73: 13219635 | E73: 12415734 | F73: 11566858 | G73: 10612250 | H73: 10067406 | I73: 10067406 | J73: 9521012.3 | K73: 8800828 | L73: 7877956 | M73: 7571598 | N73: 7571598 | O73: 7189702 | P73: 6806671 | Q73: 6482026 | R73: 6489415 | S73: 5655296 | T73: 5092284 | U73: 4654716 | V73: 4651685 | W73: 4141764 | X73: 4089767 | Y73: 3887452 | Z73: 3955520 | AA73: 3433656 | AB73: 3181874
B76: 1 - Apuração feita apenas a partir de 2020, conforme nota explicativa nº 10 das Demonstrações Financeiras de 31/12/2022
...

Sheet Inputs - DRE
B2: DIRECIONAL ENGENHARIA S.A.
B4: DEMONSTRAÇÃO DO RESULTADO (MILHARES DE R$) | C4: 2025 | D4: 4T25 | E4: 3T25 | F4: 2T25 | G4: 1T25 | H4: 2024 | I4: 4T24 | J4: 3T24 | K4: 2T24 | L4: 1T24 | M4: 2023 | N4: 4T23 | O4: 3T23 | P4: 2T23 | Q4: 1T23 | R4: 2022 | S4: 4T22 | T4: 3T22 | U4: 2T22 | V4: 1T22 | W4: 2021 | X4: 4T21 | Y4: 3T21 | Z4: 2T21 | AA4: 1T21 | AB4: 2020 | AC4: 4T20 | AD4: 3T20 | AE4: 2T20 | AF4: 1T20 | AG4: 2019 | AH4: 4T19 | AI4: 3T19 | AJ4: 2T19 | AK4: 1T19 | AL4: 2018 | AM4: 4T18 | AN4: 3T18 | AO4: 2T18 | AP4: 1T18 | AQ4: 2017 | AR4: 4T17 | AS4: 3T17 | AT4: 2T17 | AU4: 1T17 | AV4: 2016 | AW4: 4T16 | AX4: 3T16 | AY4: 2T16 | AZ4: 1T16 | BA4: 2015 | BB4: 4T15 | BC4: 3T15 | BD4: 2T15 | BE4: 1T15 | BF4: 2014 | BG4: 4T14 | BH4: 3T14 | BI4: 2T14 | BJ4: 1T14 | BK4: 2013 | BL4: 4T13 | BM4: 3T13 | BN4: 2T13 | BO4: 1T13 | BP4: 2012 | BQ4: 4T12 | BR4: 3T12 | BS4: 2T12 | BT4: 1T12
B5: RECEITA OPERACIONAL LÍQUIDA | C5: 4343008 | D5: 1225843 | E5: 1157823 | F5: 1065210 | G5: 894132 | H5: 3348470 | I5: 924210 | J5: 910598 | K5: 844220 | L5: 669442 | M5: 2355183 | N5: 634838 | O5: 557668 | P5: 605408 | Q5: 557269 | R5: 2162616 | S5: 533985 | T5: 574411 | U5: 586126 | V5: 468094 | W5: 1776380 | X5: 486971 | Y5: 453362 | Z5: 422162 | AA5: 413885 | AB5: 1500723.4 | AC5: 425314.5 | AD5: 375532 | AE5: 408408 | AF5: 291469 | AG5: 1458228 | AH5: 367685 | AI5: 367239 | AJ5: 374504 | AK5: 348800 | AL5: 1166048 | AM5: 393071 | AN5: 309919 | AO5: 270902 | AP5: 192155 | AQ5: 751857 | AR5: 169575 | AS5: 201247 | AT5: 181730 | AU5: 199305 | AV5: 1358078 | AW5: 254553 | AX5: 314586 | AY5: 383099 | AZ5: 405840 | BA5: 1569577 | BB5: 398013 | BC5: 392344 | BD5: 379400 | BE5: 399820 | BF5: 1835613 | BG5: 551144 | BH5: 462292 | BI5: 425050 | BJ5: 397128 | BK5: 1743929 | BL5: 438225 | BM5: 450848 | BN5: 466327 | BO5: 388529 | BP5: 1448779 | BQ5: 375589 | BR5: 390999 | BS5: 338164 | BT5: 344027
B6: Custo da Venda de Imóveis e Serviços Prestados | C6: -2620591 | D6: -726736 | E6: -694023 | F6: -650982 | G6: -548851 | H6: -2130127 | I6: -581814 | J6: -577881 | K6: -541592 | L6: -428840 | M6: -1550208 | N6: -425257 | O6: -365299 | P6: -400227 | Q6: -359425 | R6: -1428891 | S6: -343252 | T6: -379234 | U6: -403298 | V6: -303106 | W6: -1146299 | X6: -324610.79 | Y6: -291574.27 | Z6: -263110.64 | AA6: -267002.3 | AB6: -987413 | AC6: -281958.77 | AD6: -241802 | AE6: -276269 | AF6: -187383 | AG6: -967112 | AH6: -238010 | AI6: -244499 | AJ6: -249646 | AK6: -234958 | AL6: -849225 | AM6: -283586 | AN6: -223408 | AO6: -200676 | AP6: -141554 | AQ6: -714399 | AR6: -184646 | AS6: -186702 | AT6: -161717 | AU6: -181334 | AV6: -1201779 | AW6: -280083 | AX6: -289413 | AY6: -309670 | AZ6: -322613 | BA6: -1239094 | BB6: -317886 | BC6: -311611 | BD6: -294316 | BE6: -315281 | BF6: -1408650 | BG6: -431251 | BH6: -350223 | BI6: -322469 | BJ6: -304707 | BK6: -1340379 | BL6: -339465 | BM6: -340156 | BN6: -369432 | BO6: -291326 | BP6: -1049974 | BQ6: -269615 | BR6: -286154 | BS6: -246282 | BT6: -247923
B7: LUCRO BRUTO | C7: 1722417 | D7: 499107 | E7: 463800 | F7: 414228 | G7: 345280.63 | H7: 1218343 | I7: 342396 | J7: 332717 | K7: 302628 | L7: 240602 | M7: 804975 | N7: 209581 | O7: 192369 | P7: 205181 | Q7: 197844 | R7: 733725 | S7: 190733 | T7: 195177 | U7: 182828 | V7: 164988 | W7: 630081 | X7: 162360.21 | Y7: 161787.73 | Z7: 159051.36 | AA7: 146882.7 | AB7: 513310.43 | AC7: 143355.74 | AD7: 133730 | AE7: 132140 | AF7: 104086 | AG7: 491115 | AH7: 129675 | AI7: 122740 | AJ7: 124858 | AK7: 113842 | AL7: 316823 | AM7: 109485 | AN7: 86511 | AO7: 70226 | AP7: 50601 | AQ7: 37458 | AR7: -15071 | AS7: 14545 | AT7: 20013 | AU7: 17971 | AV7: 156299 | AW7: -25530 | AX7: 25173 | AY7: 73429 | AZ7: 83227 | BA7: 330483 | BB7: 80127 | BC7: 80733 | BD7: 85084 | BE7: 84539 | BF7: 426963 | BG7: 119893 | BH7: 112069 | BI7: 102581 | BJ7: 92420 | BK7: 403550 | BL7: 98760 | BM7: 110692 | BN7: 96895 | BO7: 97203 | BP7: 398805 | BQ7: 105974 | BR7: 104845 | BS7: 91882 | BT7: 96104
B8: Despesas Gerais e Administrativas | C8: -254781 | D8: -70378 | E8: -68636 | F8: -60634 | G8: -55133 | H8: -210307 | I8: -56546 | J8: -52276 | K8: -52355 | L8: -49129.601 | M8: -174709.76 | N8: -44598 | O8: -44731.595 | P8: -43423 | Q8: -41957 | R8: -151631 | S8: -40183 | T8: -39730 | U8: -36394 | V8: -35322 | W8: -132511 | X8: -34558.15 | Y8: -33785.25 | Z8: -33690.229 | AA8: -30477.159 | AB8: -115572 | AC8: -31595.821 | AD8: -27916 | AE8: -24736 | AF8: -31324 | AG8: -112406 | AH8: -30217 | AI8: -27314 | AJ8: -26838 | AK8: -28037 | AL8: -100301 | AM8: -25633 | AN8: -24745 | AO8: -25438 | AP8: -24485 | AQ8: -107644 | AR8: -24333 | AS8: -28267 | AT8: -28419 | AU8: -26625 | AV8: -105135 | AW8: -23840 | AX8: -25955 | AY8: -26819 | AZ8: -28521 | BA8: -105265 | BB8: -26218 | BC8: -25697 | BD8: -26394 | BE8: -26956 | BF8: -114675 | BG8: -31089 | BH8: -27917 | BI8: -25764 | BJ8: -29905 | BK8: -104395 | BL8: -25952 | BM8: -28449 | BN8: -24294 | BO8: -25700 | BP8: -97640 | BQ8: -18244 | BR8: -26905 | BS8: -25302 | BT8: -27189
B9: Despesas Comerciais | C9: -408037 | D9: -116252 | E9: -113940 | F9: -96860 | G9: -80985 | H9: -289706 | I9: -83000 | J9: -80402 | K9: -71239 | L9: -55064.805 | M9: -202241.82 | N9: -56898 | O9: -48465.697 | P9: -53518 | Q9: -43360 | R9: -203082 | S9: -52665 | T9: -52788 | U9: -52798 | V9: -44831 | W9: -190902 | X9: -53126.282 | Y9: -49548.637 | Z9: -45477.113 | AA9: -42749.82 | AB9: -158044 | AC9: -43723.28 | AD9: -39705 | AE9: -39904 | AF9: -34711 | AG9: -146206 | AH9: -38950 | AI9: -38153 | AJ9: -36432 | AK9: -32671 | AL9: -105046 | AM9: -34381 | AN9: -26864 | AO9: -24170 | AP9: -19631 | AQ9: -63288 | AR9: -21782 | AS9: -16158 | AT9: -13014 | AU9: -12334 | AV9: -50741 | AW9: -11942 | AX9: -12696 | AY9: -13056 | AZ9: -13047 | BA9: -42910 | BB9: -12611 | BC9: -11455 | BD9: -10764 | BE9: -8080 | BF9: -51723 | BG9: -12876 | BH9: -13950 | BI9: -14321 | BJ9: -10576 | BK9: -41188 | BL9: -14436 | BM9: -10276 | BN9: -10348 | BO9: -6128 | BP9: -40329 | BQ9: -8986 | BR9: -12455 | BS9: -9917 | BT9: -8971
B10: Resultado com Equivalência Patrimonial | C10: 62631 | D10: 19179 | E10: 16173 | F10: 14911 | G10: 12368 | H10: 86528 | I10: 22152 | J10: 18500 | K10: 19423 | L10: 26452.982 | M10: 53700.914 | N10: 15345 | O10: 19669.193 | P10: 11933 | Q10: 6754 | R10: 21758 | S10: 5065 | T10: 8302 | U10: 4860 | V10: 3531 | W10: 17559 | X10: 6261.0558 | Y10: 6060.0069 | Z10: 2536.5453 | AA10: 2701.3919 | AB10: 3445 | AC10: 856.3791 | AD10: 2906 | AE10: -1059 | AF10: 742 | AG10: 2394 | AH10: 369 | AI10: -383 | AJ10: 1100 | AK10: 1308 | AL10: -2339 | AM10: 501 | AN10: -1197 | AO10: -614 | AP10: -1029 | AQ10: -1380 | AR10: 115 | AS10: -513 | AT10: -350 | AU10: -632 | AV10: -1480 | AW10: -306 | AX10: 127 | AY10: -713 | AZ10: -588 | BA10: -1774 | BB10: -833 | BC10: -248 | BD10: 1439 | BE10: -2132 | BF10: 5750 | BG10: 548 | BH10: 747 | BI10: 1275 | BJ10: 3180 | BK10: 11790 | BL10: 3828 | BM10: 3475 | BN10: 3548 | BO10: 939 | BP10: 271 | BQ10: -1160 | BR10: 200 | BS10: 805 | BT10: 426
B11: Outras Receitas e Despesas Operacionais | C11: -119095 | D11: -33062 | E11: -14319 | F11: -46633 | G11: -25081 | H11: -49879 | I11: 3441 | J11: -31522 | K11: -17150 | L11: -4647.5087 | M11: -58989.301 | N11: -42231 | O11: -9689.9401 | P11: 9315 | Q11: -16383 | R11: -25357 | S11: 23575 | T11: -21872 | U11: -18234 | V11: -8827 | W11: -18387 | X11: -1387.172 | Y11: 1896.5962 | Z11: -6099.9556 | AA11: -12796.632 | AB11: -31054 | AC11: 3285.9967 | AD11: -12336 | AE11: -17526 | AF11: -4478 | AG11: -41881 | AH11: -11607 | AI11: -9019 | AJ11: -12450 | AK11: -8805 | AL11: -139954 | AM11: -19581 | AN11: -108260 | AO11: -7332 | AP11: -4782 | AQ11: 2984 | AR11: 1206 | AS11: 4983 | AT11: -2549 | AU11: -656 | AV11: 4016 | AW11: -5056 | AX11: 14387 | AY11: -1672 | AZ11: -3643 | BA11: -17267 | BB11: -48 | BC11: -4411 | BD11: -8018 | BE11: -4790 | BF11: -22657 | BG11: -13437 | BH11: -7577 | BI11: -2231 | BJ11: 588 | BK11: -11036 | BL11: -3260 | BM11: -4327 | BN11: -396 | BO11: -3053 | BP11: -7165 | BQ11: -4164 | BR11: -2335 | BS11: -1230 | BT11: 564
B12: Despesas Financeiras | C12: -347061 | D12: -113765 | E12: -92014 | F12: -79992 | G12: -61290 | H12: -256789 | I12: -91503 | J12: -59330 | K12: -65707 | L12: -40248.694 | M12: -288045.12 | N12: -73935 | O12: -75550.891 | P12: -69299 | Q12: -69260 | R12: -269367 | S12: -74805 | T12: -68711 | U12: -65049 | V12: -60801 | W12: -157347 | X12: -61886.735 | Y12: -39944.088 | Z12: -26862.088 | AA12: -28654.088 | AB12: -84083 | AC12: -30413.681 | AD12: -16297 | AE12: -17375 | AF12: -19997 | AG12: -80156 | AH12: -18376 | AI12: -20972 | AJ12: -19842 | AK12: -20966 | AL12: -58858 | AM12: -14281 | AN12: -15823 | AO12: -15042 | AP12: -13712 | AQ12: -42998 | AR12: -9977 | AS12: -13221 | AT12: -8709 | AU12: -11091 | AV12: -50278 | AW12: -11515 | AX12: -14181 | AY12: -14451 | AZ12: -10131 | BA12: -48752 | BB12: -12210 | BC12: -12279 | BD12: -12196 | BE12: -12067 | BF12: -45969 | BG12: -12406 | BH12: -12812 | BI12: -12383 | BJ12: -8368 | BK12: -31111 | BL12: -8115 | BM12: -8707 | BN12: -6686 | BO12: -7603 | BP12: -15108 | BQ12: -6860 | BR12: -2970 | BS12: -2570 | BT12: -2708
B13: Receitas Financeiras | C13: 422421 | D13: 127549 | E13: 119310 | F13: 98161 | G13: 77401 | H13: 294108 | I13: 84674 | J13: 76764.078 | K13: 69213 | L13: 63456.853 | M13: 302169.02 | N13: 120692 | O13: 63367.256 | P13: 68147 | Q13: 49962 | R13: 195489 | S13: 54132 | T13: 70823 | U13: 34226 | V13: 36308 | W13: 80632 | X13: 38182.27 | Y13: 20724.728 | Z13: 12895.798 | AA13: 8828.9353 | AB13: 44116 | AC13: 10449.83 | AD13: 8381 | AE13: 15982 | AF13: 9304 | AG13: 40941 | AH13: 9377 | AI13: 12780 | AJ13: 9122 | AK13: 9662 | AL13: 38347 | AM13: 9744 | AN13: 10278 | AO13: 8762 | AP13: 9563 | AQ13: 54158 | AR13: 14234 | AS13: 14058 | AT13: 10303 | AU13: 15563 | AV13: 67521 | AW13: 16622 | AX13: 19314 | AY13: 17980 | AZ13: 13605 | BA13: 64983 | BB13: 15437 | BC13: 16336 | BD13: 16043 | BE13: 17167 | BF13: 57838 | BG13: 16896 | BH13: 16263 | BI13: 14289 | BJ13: 10390 | BK13: 32586 | BL13: 9255 | BM13: 8180 | BN13: 8348 | BO13: 6803 | BP13: 38870 | BQ13: 10730 | BR13: 7030 | BS13: 10078 | BT13: 11032
B14: RESULTADO ANTES DO IMPOSTO DE RENDA E CONTRIBUIÇÃO SOCIAL | C14: 1078495 | D14: 312379 | E14: 310375 | F14: 243181 | G14: 212561 | H14: 792298 | I14: 221614 | J14: 204451.08 | K14: 184813 | L14: 181420.23 | M14: 436858.93 | N14: 127956 | O14: 96966.326 | P14: 128335 | Q14: 83600 | R14: 301535 | S14: 105851 | T14: 91199 | U14: 49439 | V14: 55046 | W14: 229125 | X14: 55845.193 | Y14: 67191.087 | Z14: 62354.318 | AA14: 43735.33 | AB14: 172118.43 | AC14: 52215.159 | AD14: 48761 | AE14: 47521 | AF14: 23620 | AG14: 153801 | AH14: 40272 | AI14: 39678 | AJ14: 39518 | AK14: 34333 | AL14: -51328 | AM14: 25854 | AN14: -80100 | AO14: 6392 | AP14: -3475 | AQ14: -120710 | AR14: -55608 | AS14: -24573 | AT14: -22725 | AU14: -17804 | AV14: 20202 | AW14: -61567 | AX14: 6169 | AY14: 34698 | AZ14: 40902 | BA14: 179498 | BB14: 43644 | BC14: 42979 | BD14: 45194 | BE14: 47681 | BF14: 255527 | BG14: 67529 | BH14: 66823 | BI14: 63446 | BJ14: 57729 | BK14: 260196 | BL14: 60080 | BM14: 70588 | BN14: 67067 | BO14: 62461 | BP14: 277704 | BQ14: 77290 | BR14: 67410 | BS14: 63746 | BT14: 69258
B15: Imposto de Renda e Contribuição Social - Corrente e Diferido | C15: -98803 | D15: -27756 | E15: -27400 | F15: -22538 | G15: -21109 | H15: -64630.454 | I15: -17545 | J15: -19761.094 | K15: -14901 | L15: -12423.359 | M15: -49981.552 | N15: -13991 | O15: -11091.38 | P15: -13564 | Q15: -11335 | R15: -45846 | S15: -11224 | T15: -12246 | U15: -12572 | V15: -9805 | W15: -35563 | X15: -9904.0602 | Y15: -8254.5454 | Z15: -9448.27 | AA15: -7956.2747 | AB15: -31110 | AC15: -9178.8077 | AD15: -7567 | AE15: -8468 | AF15: -5897 | AG15: -32986 | AH15: -9331 | AI15: -8516 | AJ15: -7560 | AK15: -7579 | AL15: -22608 | AM15: -7463 | AN15: -4787 | AO15: -5805 | AP15: -4553 | AQ15: -16725 | AR15: -5079 | AS15: -4218 | AT15: -3237 | AU15: -4191 | AV15: -21599 | AW15: -4818 | AX15: -4747 | AY15: -5585 | AZ15: -6449 | BA15: -23288 | BB15: -5271 | BC15: -5900 | BD15: -6652 | BE15: -5465 | BF15: -23311 | BG15: -7001 | BH15: -5273 | BI15: -5836 | BJ15: -5201 | BK15: -23742 | BL15: -6038 | BM15: -6167 | BN15: -5942 | BO15: -5595 | BP15: -20237 | BQ15: 4367 | BR15: -7680 | BS15: -7907 | BT15: -9017
B16: RESULTADO LÍQUIDO ANTES DOS PARTICIPANTES EM SCPs E SPEs | C16: 979692 | D16: 284623 | E16: 282974 | F16: 220643 | G16: 191452 | H16: 727668.38 | I16: 204069 | J16: 184689.98 | K16: 169912 | L16: 168996.87 | M16: 386877.38 | N16: 113965 | O16: 85874.946 | P16: 114771 | Q16: 72265 | R16: 255689 | S16: 94628 | T16: 78953 | U16: 36867 | V16: 45241 | W16: 193562 | X16: 45941.133 | Y16: 58936.542 | Z16: 52906.048 | AA16: 35779.055 | AB16: 141008.43 | AC16: 43036.351 | AD16: 41194 | AE16: 39053 | AF16: 17723 | AG16: 120816 | AH16: 30941 | AI16: 31163 | AJ16: 31958 | AK16: 26754 | AL16: -73936 | AM16: 18391 | AN16: -84887 | AO16: 587 | AP16: -8028 | AQ16: -137435 | AR16: -60687 | AS16: -28791 | AT16: -25962 | AU16: -21995 | AV16: -1397 | AW16: -66385 | AX16: 1422 | AY16: 29113 | AZ16: 34453 | BA16: 156210 | BB16: 38373 | BC16: 37079 | BD16: 38542 | BE16: 42216 | BF16: 232216 | BG16: 60528 | BH16: 61550 | BI16: 57610 | BJ16: 52528 | BK16: 236454 | BL16: 54042 | BM16: 64421 | BN16: 61125 | BO16: 56866 | BP16: 257467 | BQ16: 81657 | BR16: 59730 | BS16: 55839 | BT16: 60241
... B18: LUCRO LÍQUIDO DO PERÍODO | C18: 789342 | D18: 211432 | E18: 229652 | F18: 183742 | G18: 164516 | H18: 638378.21 | I18: 181461 | J18: 160463.98 | K18: 146169 | L18: 150283.7 | M18: 331560.3 | N18: 99606 | O18: 68762.946 | P18: 104439 | Q18: 58754 | R18: 190020 | S18: 78605 | T18: 62272 | U18: 22436 | V18: 26707 | W18: 146603 | X18: 31958.815 | Y18: 47210.112 | Z18: 40623.207 | AA18: 26811.644 | AB18: 104968.43 | AC18: 32465.014 | AD18: 28555 | AE18: 33894 | AF18: 10052 | AG18: 100477 | AH18: 28213 | AI18: 25951 | AJ18: 25900 | AK18: 20413 | AL18: -77495 | AM18: 18197 | AN18: -83821 | AO18: -3778 | AP18: -8093 | AQ18: -143781 | AR18: -61884 | AS18: -29390 | AT18: -29727 | AU18: -22780 | AV18: -11862 | AW18: -64811 | AX18: 1116 | AY18: 22195 | AZ18: 29638 | BA18: 123647 | BB18: 30824 | BC18: 28804 | BD18: 27784 | BE18: 36235 | BF18: 205870 | BG18: 60735 | BH18: 52246 | BI18: 46566 | BJ18: 46323 | BK18: 228197 | BL18: 50484 | BM18: 62112 | BN18: 60864 | BO18: 54737 | BP18: 225038 | BQ18: 72745 | BR18: 54675 | BS18: 46485 | BT18: 51133
C20: =C11/C5 -> -0.027422238 | D20: =D11/D5 -> -0.026970827 | E20: =E11/E5 -> -0.012367175 | F20: =F11/F5 -> -0.043778222 | G20: =G11/G5 -> -0.028050668 | H20: =H11/H5 -> -0.014896057 | I20: =I11/I5 -> 0.0037231798 | J20: =J11/J5 -> -0.034616812 | ... R20: =R11/R5 -> -0.011725151
E27: =AVERAGE(C20,H20,M20,R20) -> -0.019772509

Sheet Inputs - Operacionais
B2: DIRECIONAL ENGENHARIA S.A.
B4: DADOS OPERACIONAIS (MILHARES DE R$) | C4: 2025 | D4: 4T25 | E4: 3T25 | F4: 2T25 | G4: 1T25 | H4: 2024 | I4: 4T24 | J4: 3T24 | K4: 2T24 | L4: 1T24 | M4: 2023 | N4: 4T23 | O4: 3T23 | P4: 2T23 | Q4: 1T23 | R4: 2022 | S4: 4T22 | T4: 3T22 | U4: 2T22 | V4: 1T22 | W4: 2021 | X4: 4T21 | Y4: 3T21 | Z4: 2T21 | AA4: 1T21 | AB4: 2020 | AC4: 4T20 | AD4: 3T20 | AE4: 2T20 | AF4: 1T20 | AG4: 2019 | AH4: 4T19 | AI4: 3T19 | AJ4: 2T19 | AK4: 1T19 | AL4: 2018 | AM4: 4T18 | AN4: 3T18 | AO4: 2T18 | AP4: 1T18 | AQ4: 2017 | AR4: 4T17 | AS4: 3T17 | AT4: 2T17 | AU4: 1T17 | AV4: 2016 | AW4: 4T16 | AX4: 3T16 | AY4: 2T16 | AZ4: 1T16 | BA4: 2015 | BB4: 4T15 | BC4: 3T15 | BD4: 2T15 | BE4: 1T15 | BF4: 2014 | BG4: 4T14 | BH4: 3T14 | BI4: 2T14 | BJ4: 1T14 | BK4: 2013 | BL4: 4T13 | BM4: 3T13 | BN4: 2T13 | BO4: 1T13 | BP4: 2012 | BQ4: 4T12 | BR4: 3T12 | BS4: 2T12 | BT4: 1T12
B5: LANÇAMENTOS
B6: VGV Lançado (R$ mil) | C6: 6857548 | D6: 1900910.3 | E6: 2151576.7 | F6: 1903899.2 | G6: 901161.78 | H6: 5754715.4 | I6: 1833172.7 | J6: 1664372.7 | K6: 1360653 | L6: 896517.01 | M6: 4857453.4 | N6: 1390197 | O6: 1399420.2 | P6: 1456646.1 | Q6: 611190.03 | R6: 3636218.9 | S6: 1057713.1 | T6: 1189068.1 | U6: 790369.12 | V6: 599068.63 | W6: 3137983.8 | X6: 693380.72 | Y6: 1080620.3 | Z6: 786922.92 | AA6: 577059.8 | AB6: 1762850.4 | AC6: 697306.98 | AD6: 574480.16 | AE6: 351171 | AF6: 139892 | AG6: 1946038 | AH6: 555128 | AI6: 436682 | AJ6: 562020 | AK6: 392208 | AL6: 1904853 | AM6: 528679 | AN6: 528371 | AO6: 366245 | AP6: 481559 | AQ6: 1108693 | AR6: 490673 | AS6: 115290 | AT6: 299477 | AU6: 203253 | AV6: 832435.62 | AW6: 352335.43 | AX6: 169574.89 | AY6: 209544.97 | AZ6: 100980.33 | BA6: 501833.7 | BB6: 227169.87 | BC6: 72428.052 | BD6: 174331.77 | BE6: 27904 | BF6: 1798989.9 | BG6: 351772.69 | BH6: 412789.31 | BI6: 262924 | BJ6: 771503.9 | BK6: 2851266.7 | BL6: 972083.04 | BM6: 908112.16 | BN6: 551274.07 | BO6: 419797.38 | BP6: 2502500 | BQ6: 1222262.5 | BR6: 604949.61 | BS6: 531950.14 | BT6: 143337.76
